<?xml version="1.0"?>
<robot xmlns:xacro="http://www.ros.org/wiki/xacro" name="tangerige">


<!-- .......................MACROS.................... -->
  
  <xacro:macro name="default_physics" params="mass len rad">
  	<collision>
      <geometry>
        <cylinder length="${len}" radius="${rad}"/>
      </geometry>
    </collision>
  	<inertial>
  		<mass value="${mass}" />
  		<inertia ixx="1.0" ixy="0.0" ixz="0.0"
  											 iyy="1.0" iyz="0.0"
  											 izz="1.0" />
  	</inertial>
  	<dynamics damping="0.7" friction="1000.0"/>
  </xacro:macro>
  
  <xacro:macro name="gazebo_colors" params="name color">
  	<gazebo reference="${name}">
    	<material>Gazebo/${color}</material>
  	</gazebo>
  </xacro:macro>
  
<!-- ....................... END MACROS.................... -->

<!-- ................BASE................. -->
  
  <link name="base_laser">
    <visual>
      <geometry>
        <box size="0.176 0.15 0.4"/>
      </geometry>
      <material name="grey">
      	<color rgba="0.5 0.5 0.5 1"/>
      </material>
      <origin rpy="0 0 1.57075"/>
    </visual>
  </link>
  
  <xacro:gazebo_colors name="base_laser" color="Red" />
  
  <link name="base_link_robot">
    <visual>
      <geometry>
        <box size="0.51 0.51 0.2"/>
      </geometry>
      <material name="orange">
      	<color rgba=".8 .2 0 1"/>
      </material>
    </visual>
  </link>
  
  <xacro:gazebo_colors name="base_link" color="Red" />
  
  <joint name="laser_to_base_link" type="fixed">
    <parent link="base_laser"/>
    <child link="base_link_robot"/>
    <origin xyz="0.093 0 -0.3"/>
  </joint>

  <link name="upper_base_laser">
    <visual>
      <geometry>
        <box size="0.176 0.15 0.15"/>
      </geometry>
      <material name="grey"/>
    </visual>
  </link>
  
  <xacro:gazebo_colors name="upper_base_laser" color="Gray" />
  
  <joint name="laser_to_upper_base" type="fixed">
    <parent link="base_laser"/>
    <child link="upper_base_laser"/>
    <origin rpy="0 0 -1.57075" xyz="0 0 0.275"/>
  </joint>
  
  <link name="superior_link">
    <visual>
      <geometry>
        <box size="0.300 0.360 0.4"/>
      </geometry>
      <material name="black">
      	<color rgba="0 0 0 1"/>
      </material>
    </visual>
  </link>
  
  <xacro:gazebo_colors name="superior_link" color="Black" />
  
  <joint name="upper_base_to_superior_link" type="fixed">
    <parent link="upper_base_laser"/>
    <child link="superior_link"/>
    <origin xyz="0 0 0.275"/>
  </joint>
  
  <!-- ................END BASE................. -->
  
  
  <!-- ................HEAD................. -->
  
  <link name="neck_link">
    <visual>
      <geometry>
        <box size="0.05 0.08 0.07"/>
      </geometry>
      <material name="grey"/>
    </visual>
  </link>
  
  <xacro:gazebo_colors name="neck_link" color="Red" />
  
  <joint name="superior_to_neck_link" type="fixed">
    <parent link="superior_link"/>
    <child link="neck_link"/>
    <origin xyz="0 0 0.235"/>
  </joint>
  
  <link name="neck_z_revolute">
  </link>
<!-- These joint are really revolute...change them back! -->  
  <joint name="neck_to_z_revolute" type="fixed">
  	<axis xyz="0 0 1"/>
  	<limit effort="1000.0" lower="-0.7853" upper="0.7853" velocity="5"/>
    <parent link="neck_link"/>
    <child link="neck_z_revolute"/>
  </joint>
  
  <link name="neck_x_revolute">
  </link>
  
  <joint name="z_revolute_to_x_revolute" type="fixed">
  	<axis xyz="1 0 0"/>
  	<limit effort="1000.0" lower="-0.3926" upper="0.3926" velocity="5"/>
    <parent link="neck_z_revolute"/>
    <child link="neck_x_revolute"/>
  </joint>
  
  <link name="head">
    <visual>
      <geometry>
        <box size="0.222 0.065 0.18"/>
      </geometry>
      <material name="orange"/>
    </visual>
  </link>
  
  <xacro:gazebo_colors name="head" color="Red" />
  
  <joint name="revolute_head" type="fixed">
    <parent link="neck_x_revolute"/>
    <child link="head"/>
    <origin xyz="0 0 0.125"/>
  </joint>
  
  <link name="right_eye">
    <visual>
      <geometry>
        <cylinder length="0.015" radius="0.015"/>
      </geometry>
      <material name="black"/>
      <origin rpy="-1.57075 0 0" />
    </visual>
  </link>
  
  <joint name="right_eye_to_head" type="fixed">
    <parent link="head"/>
    <child link="right_eye"/>
    <origin xyz="0.05 0.03 0.03"/>
  </joint>
  
  <link name="left_eye">
    <visual>
      <geometry>
        <cylinder length="0.015" radius="0.015"/>
      </geometry>
      <material name="black"/>
      <origin rpy="-1.57075 0 0" />
    </visual>
  </link>
  
  <joint name="left_eye_to_head" type="fixed">
    <parent link="head"/>
    <child link="left_eye"/>
    <origin xyz="-0.05 0.03 0.03"/>
  </joint>
  
  <!-- ................END HEAD................. -->
  
  
  <!-- ................RIGHT ARM................. -->
  
  <link name="right_shoulder_link">
    <visual>
      <geometry>
        <box size="0.01 0.14 0.17"/>
      </geometry>
      <origin xyz="0.05 0 -0.05" rpy="0 1.57075 0"/>
      <material name="orange"/>
    </visual>
  </link>
  
  <xacro:gazebo_colors name="right_shoulder_link" color="Gray" />
  
  <joint name="superior_link_to_right_shoulder" type="fixed">
    <parent link="superior_link"/>
    <child link="right_shoulder_link"/>
    <origin xyz="0.205 0 0.12" rpy="0 1.57075 0"/>
  </joint>

  <link name="right_shoulder_x_revolute">   
  </link>
  
  <xacro:gazebo_colors name="right_shoulder_x_revolute" color="Gray" />
  
  <joint name="right_shoulder_x_revolute" type="revolute">
  	<axis xyz="0 0 1"/>
  	<limit effort="1000.0" lower="-0.34906585" upper="3.351032164" velocity="5"/>
    <parent link="right_shoulder_link"/>
    <child link="right_shoulder_x_revolute"/>
    <origin xyz="0 0 0" rpy="0 0 0"/>
  </joint>
  
  <link name="right_shoulder_y_revolute">
  	<visual>
      <geometry>
        <box size="0.09 0.17 0.14"/>
      </geometry>
      <origin xyz="0 0 0" rpy="0 0 0"/>
      <material name="grey"/>
    </visual>
  </link>
  
  <joint name="right_shoulder_y_revolute" type="revolute">
  	<axis xyz="0 0 1"/>
  	<limit effort="1000.0" lower="-3.490658504" upper="-1.483529864" velocity="5"/>
    <parent link="right_shoulder_x_revolute"/>
    <child link="right_shoulder_y_revolute"/>
    <origin xyz="0 0 0" rpy="-1.57075 0 0"/>
  </joint>
     
  <link name="upper_right_arm_z_revolute">
  	<visual>
      <geometry>
        <box size="0.08 0.065 -0.154"/>
      </geometry>
      <origin xyz="0 0 -0.077" rpy="0 0 0"/>
      <material name="grey"/>
    </visual>   	
  </link>
  
  <joint name="upper_right_arm_z_revolute" type="revolute">
  	<axis xyz="0 0 1"/>
  	<limit effort="1000.0" lower="-3.403392041" upper="0.261799388" velocity="5"/>
    <parent link="right_shoulder_y_revolute"/>
    <child link="upper_right_arm_z_revolute"/>
    <origin xyz="0 0.239 0" rpy="-1.57075 0 0"/>
  </joint>
  
  <link name="upper_right_arm_x_revolute">
  	<visual>
      <geometry>
        <box size="0.08 0.232 0.065"/>
      </geometry>
      <origin xyz="0 0.116 0" rpy="0 0 0"/>
      <material name="grey"/>
    </visual>
  </link>
  
  <xacro:gazebo_colors name="upper_right_arm_x_revolute" color="Gray" />
  
  <joint name="upper_right_arm_x_revolute" type="revolute">
  	<axis xyz="0 0 1"/>
  	<limit effort="1000.0" lower="-2.251474735" upper="1.570796327" velocity="0"/>
    <parent link="upper_right_arm_z_revolute"/>
    <child link="upper_right_arm_x_revolute"/>
    <origin xyz="0 0 0" rpy="1.57075 0 0"/>
  </joint>
  
  <link name="wrist_right_arm_z_revolute">
  </link>
  
  <joint name="wrist_right_arm_z_revolute" type="revolute">
  	<axis xyz="0 0 1"/>
  	<limit effort="1000.0" lower="0" upper="3.141592654" velocity="5"/>
    <parent link="upper_right_arm_x_revolute"/>
    <child link="wrist_right_arm_z_revolute"/>
    <origin xyz="0 0.232 0" rpy="-1.57075 0 0"/>
  </joint>
  
  <link name="wrist_right_arm_x_revolute">
  </link>
  
  <joint name="wrist_right_arm_x_revolute" type="revolute">
  	<axis xyz="0 0 1"/>
  	<limit effort="1000.0" lower="-1.047197551" upper="1.483529864" velocity="5"/>
    <parent link="wrist_right_arm_z_revolute"/>
    <child link="wrist_right_arm_x_revolute"/>
    <origin xyz="0 0 0" rpy="1.57075 0 0"/>
  </joint>
  
  <link name="wrist_right_arm">
    <visual>
      <geometry>
        <box size="0.065 0.069 0.08"/>
      </geometry>
      <origin xyz="0 -0.0345 0" rpy="0 0 0"/>
      <material name="black"/>
    </visual>
  </link>
  
  <xacro:gazebo_colors name="wrist_right_arm" color="Black" />
  
  <joint name="wrist_right_arm" type="fixed">
    <parent link="wrist_right_arm_x_revolute"/>
    <child link="wrist_right_arm"/>
    <origin xyz="0 0.069 0"/>
  </joint>
  
  <link name="finger1_right_arm">
    <visual>
      <geometry>
        <box size="0.01 0.05 0.03"/>
      </geometry>
      <origin xyz="0 0.025 0" />
      <material name="grey"/>
    </visual>
  </link>
  
  <xacro:gazebo_colors name="finger1_right_arm" color="Gray" />
  
  <joint name="finger1_right_arm" type="fixed">
    <parent link="wrist_right_arm"/>
    <child link="finger1_right_arm"/>
    <origin rpy="0 0 0" xyz="-0.01875 0 0"/>
  </joint>
  
  <link name="finger2_right_arm">
    <visual>
      <geometry>
        <box size="0.01 0.05 0.05"/>
      </geometry>
      <origin xyz="0 0.025 0" />
      <material name="grey"/>
    </visual>
  </link>
  
  <xacro:gazebo_colors name="finger2_right_arm" color="Gray" />
  
  <joint name="finger2_right_arm" type="fixed">
    <parent link="wrist_right_arm"/>
    <child link="finger2_right_arm"/>
    <origin rpy="0 0 0" xyz="0.01875 0 0"/>
  </joint>
  
  <!-- ................END RIGHT ARM................. -->
  
  
  
    <!-- ................LEFT ARM................. -->

   <link name="left_shoulder_link">
    <visual>
      <geometry>
        <box size="0.01 0.14 0.17"/>
      </geometry>
      <origin xyz="0.05 0 0.05" rpy="0 1.57075 0"/>
      <material name="orange"/>
    </visual>
  </link>
  
  <xacro:gazebo_colors name="left_shoulder_link" color="Gray" />
  
  <joint name="superior_link_to_left_shoulder" type="fixed">
    <parent link="superior_link"/>
    <child link="left_shoulder_link"/>
    <origin xyz="-0.205 0 0.12" rpy="0 1.57075 0"/>
  </joint>

  <link name="left_shoulder_x_revolute">   
  </link>
  
  <xacro:gazebo_colors name="left_shoulder_x_revolute" color="Gray" />
  
  <joint name="left_shoulder_x_revolute" type="revolute">
  	<axis xyz="0 0 1"/>
  	<limit effort="1000.0" lower="-0.34906585" upper="3.351032164" velocity="5"/>
    <parent link="left_shoulder_link"/>
    <child link="left_shoulder_x_revolute"/>
    <origin xyz="0 0 0" rpy="0 0 0"/>
  </joint>
  
  <link name="left_shoulder_y_revolute">
  	<visual>
      <geometry>
        <box size="0.09 0.17 0.14"/>
      </geometry>
      <origin xyz="0 0 0" rpy="0 0 0"/>
      <material name="grey"/>
    </visual>
  </link>
  
  <joint name="left_shoulder_y_revolute" type="revolute">
  	<axis xyz="0 0 1"/>
  	<limit effort="1000.0" lower="-3.490658504" upper="-1.483529864" velocity="5"/>
    <parent link="left_shoulder_x_revolute"/>
    <child link="left_shoulder_y_revolute"/>
    <origin xyz="0 0 0" rpy="1.57075 0 0"/>
  </joint>
     
  <link name="upper_left_arm_z_revolute">
  	<visual>
      <geometry>
        <box size="0.08 0.065 -0.154"/>
      </geometry>
      <origin xyz="0 0 0.077" rpy="0 0 0"/>
      <material name="grey"/>
    </visual> 	
  </link>
  
  <joint name="upper_left_arm_z_revolute" type="revolute">
  	<axis xyz="0 0 1"/>
  	<limit effort="1000.0" lower="-3.403392041" upper="0.261799388" velocity="5"/>
    <parent link="left_shoulder_y_revolute"/>
    <child link="upper_left_arm_z_revolute"/>
    <origin xyz="0 0.239 0" rpy="1.57075 0 0"/>
  </joint>
  
  <link name="upper_left_arm_x_revolute">
  	<visual>
      <geometry>
        <box size="0.08 0.232 0.065"/>
      </geometry>
      <origin xyz="0 0.116 0" rpy="0 0 0"/>
      <material name="grey"/>
    </visual>
  </link>
  
  <xacro:gazebo_colors name="upper_left_arm_x_revolute" color="Gray" />
  
  <joint name="upper_left_arm_x_revolute" type="revolute">
  	<axis xyz="0 0 1"/>
  	<limit effort="1000.0" lower="-2.251474735" upper="1.570796327" velocity="0"/>
    <parent link="upper_left_arm_z_revolute"/>
    <child link="upper_left_arm_x_revolute"/>
    <origin xyz="0 0 0" rpy="-1.57075 0 0"/>
  </joint>
  
  <link name="wrist_left_arm_z_revolute">
  </link>
  
  <joint name="wrist_left_arm_z_revolute" type="revolute">
  	<axis xyz="0 0 1"/>
  	<limit effort="1000.0" lower="0" upper="3.141592654" velocity="5"/>
    <parent link="upper_left_arm_x_revolute"/>
    <child link="wrist_left_arm_z_revolute"/>
    <origin xyz="0 0.232 0" rpy="1.57075 0 0"/>
  </joint>
  
  <link name="wrist_left_arm_x_revolute">
  </link>
  
  <joint name="wrist_left_arm_x_revolute" type="revolute">
  	<axis xyz="0 0 1"/>
  	<limit effort="1000.0" lower="-1.047197551" upper="1.483529864" velocity="5"/>
    <parent link="wrist_left_arm_z_revolute"/>
    <child link="wrist_left_arm_x_revolute"/>
    <origin xyz="0 0 0" rpy="-1.57075 0 0"/>
  </joint>
  
  <link name="wrist_left_arm">
    <visual>
      <geometry>
        <box size="0.065 0.069 0.08"/>
      </geometry>
      <origin xyz="0 -0.0345 0" rpy="0 0 0"/>
      <material name="black"/>
    </visual>
  </link>
  
  <xacro:gazebo_colors name="wrist_left_arm" color="Black" />
  
  <joint name="wrist_left_arm" type="fixed">
    <parent link="wrist_left_arm_x_revolute"/>
    <child link="wrist_left_arm"/>
    <origin xyz="0 0.069 0"/>
  </joint>
  
  <link name="finger1_left_arm">
    <visual>
      <geometry>
        <box size="0.01 0.05 0.03"/>
      </geometry>
      <origin xyz="0 0.025 0" />
      <material name="grey"/>
    </visual>
  </link>
  
  <xacro:gazebo_colors name="finger1_left_arm" color="Gray" />
  
  <joint name="finger1_left_arm" type="fixed">
    <parent link="wrist_left_arm"/>
    <child link="finger1_left_arm"/>
    <origin rpy="0 0 0" xyz="-0.01875 0 0"/>
  </joint>
  
  <link name="finger2_left_arm">
    <visual>
      <geometry>
        <box size="0.01 0.05 0.05"/>
      </geometry>
      <origin xyz="0 0.025 0" />
      <material name="grey"/>
    </visual>
  </link>
  
  <xacro:gazebo_colors name="finger2_left_arm" color="Gray" />
  
  <joint name="finger2_left_arm" type="fixed">
    <parent link="wrist_left_arm"/>
    <child link="finger2_left_arm"/>
    <origin rpy="0 0 0" xyz="0.01875 0 0"/>
  </joint>
  
  <!-- ................END LEFT ARM................. -->
  
</robot>
